Workbook

Sheet semaine 52 n-1
A1: Menu du : | C1: =A5 -> 46377 | D1: AU | E1: =A35 -> 46383
B2: Midi | D2: Soir
A4: Lundi
A5: ='semaine 52'!A5 -> 46377
A9: Mardi
A10: =A5+1 -> 46378
A14: Mercredi
A15: =A10+1 -> 46379
A19: Jeudi
A20: =A15+1 -> 46380
A24: Vendredi
A25: =A20+1 -> 46381
A29: Samedi
A30: =A25+1 -> 46382
A34: Dimanche
A35: =A30+1 -> 46383

Sheet semaine 1
A1: Menu du : | C1: =A6 -> 46384 | D1: AU | E1: =A35 -> 46390
B2: Midi | D2: Soir
B3: Taboulé | D3: Mache
A4: Lundi | B4: Paupiette de volaile | C4: France | D4: Jambon Blanc | E4: France
B5: Choux fleur | D5: pomme de terre rissolées
A6: ='semaine 52 n-1'!A35+1 -> 46384 | B6: Fromage | D6: Yaourt
B7: Fruit | D7: Fruit
B8: Poireau en salade | D8: Potage de Légumes
A9: Mardi | B9: tartiflette | C9: France | D9: œuf mayonnaise
A10: =A6+1 -> 46385 | D10: salsifi
D11: Yaourt
B12: Dessert | D12: Fruit
B13: Salade de lentille | D13: Velouté de cépes chataigne
A14: Mercredi | B14: Suprême de volaille | C14: France | D14: Croustade escargots
A15: =A10+1 -> 46386 | B15: Haricots verts | D15: Duo de carottes
B16: Fromage | D16: Yaourt bio
B17: Fruit | D17: Entremets croustillant chocolat
B18: salade périgoudine | D18: Soupe de poisson
A19: Jeudi | B19: Filet mignon au cidre | C19: France | D19: Feuilleté
A20: =A15+1 -> 46387 | B20: Risotto | D20: Crumble de légumes
B21: Fromage | D21: Yaourt
B22: Entremet vanille Fruit rouge | D22: Fruit
B23: Paté aux olives | D23: Terrine de légumes
A24: Vendredi | B24: Pavé de poisson | D24: Qunelle de volaille
A25: =A20+1 -> 46388 | B25: Riz | D25: carottes
B26: Fromage | D26: Yaourt
B27: Fruit | D27: Fruit
B28: salade de Pâtess | D28: Potage de Légumes
A29: Samedi | B29: Roti de porc | C29: France | D29: lasagne au bœuf | E29: France
A30: =A25+1 -> 46389 | B30: Choux rpmanesco
B31: Fromage | D31: Yaourt
B32: Fruit | D32: Fruit
B33: salade verte | D33: carottes rapées
A34: Dimanche | B34: escalope milanaise | C34: France | D34: dos de colin meunière | E34: France
A35: =A30+1 -> 46390 | B35: semoule | D35: rapé de pomme de terre
B36: Fromage | D36: Yaourt
B37: Dessert | D37: Fruit

Sheet semaine 2
A1: Menu du : | C1: =A6 -> 46391 | D1: AU | E1: =A35 -> 46397
B2: Midi | D2: Soir
B3: Salade verte | D3: Salade de Perles
A4: Lundi | B4: Sauté de Lapin | C4: France | D4: Endives au Jambon | E4: France
B5: Choux de Bruxelles
A6: ='semaine 1'!A35+1 -> 46391 | B6: Fromage | D6: Yaourt
B7: Fruit | D7: Fruit
B8: Salade Coleslow | D8: Potage de Légumes
A9: Mardi | B9: Croziflette | C9: France | D9: Chipolatas | E9: France
A10: =A6+1 -> 46392 | D10: Haricots blanc
D11: Yaourt
B12: Dessert | D12: Fruit
B13: Taboulé | D13: Macédoine de Légumes
A14: Mercredi | B14: Escalope dinde | C14: France | D14: Raviolis | E14: France
A15: =A10+1 -> 46393 | B15: gratin de potimarron
B16: Fromage | D16: Yaourt
B17: Fruit | D17: Fruit
B18: Salade de Chou Chinois | D18: Potage de Féculents
A19: Jeudi | B19: Saucisse | C19: France | D19: Œuf béchamel
A20: =A15+1 -> 46394 | B20: Aligot | D20: Haricots beurre
D21: Yaourt
B22: Fruit | D22: Fruit
B23: Mousse de Canard | D23: Salade d'endives
A24: Vendredi | B24: Saumon | D24: Chili con carne | E24: France
A25: =A20+1 -> 46395 | B25: Chou Romanesco
B26: Fromage | D26: Yaourt
B27: Fruit | D27: Fruit
B28: Carottes Rapées | D28: Potage de Légumes
A29: Samedi | B29: Flecque | C29: France | D29: Pates Carbonara | E29: France
A30: =A25+1 -> 46396
B31: Fromage | D31: Yaourt
B32: Fruit | D32: Fruit
B33: Salade verte | D33: Salade de Riz
A34: Dimanche | B34: Rôti de Veau | C34: France | D34: maquereaux
A35: =A30+1 -> 46397 | B35: Lentilles | D35: Poelée de légumes
B36: Fromage | D36: Yaourt
B37: Dessert | D37: Fruit

Sheet semaine 3
A1: Menu du : | C1: =A5 -> 45669 | D1: AU | E1: =A35 -> 45675
B2: Midi | D2: Soir
B3: Tranche de Jambon Cru | D3: Poireaux vinaigrette
A4: Lundi | B4: Pavé de Poisson | D4: Escalope viennoise | E4: France
A5: 45669 | B5: Epinards à la crème | D5: Riz
B6: Fromage | D6: Yaourt
B7: Fruit | D7: Fruit
B8: Avocat | D8: Potage de Légumes
A9: Mardi | B9: Pot au feu | C9: France | D9: Pâtess Bolognaise
A10: =A5+1 -> 45670
B11: Fromage | D11: Yaourt
B12: Dessert | D12: Fruit
B13: Feuilleté | D13: Taboulé
A14: Mercredi | B14: Sûprèmes de Volaille | C14: France | D14: Langue de Bœuf Sauce Piquante | E14: Brésil
A15: =A10+1 -> 45671 | B15: Petit Pois | D15: Côtes de Blette
B16: Fromage | D16: Yaourt
B17: Fruit | D17: Fruit
B18: Salade d'Endives | D18: Potage de Féculents
A19: Jeudi | B19: Choucroute | C19: France | D19: Mortadelle | E19: France
A20: =A15+1 -> 45672 | D20: Carottes Persillées
B21: Fromage | D21: Yaourt
B22: Fruit | D22: Fruit
B23: Salade Mexicaine | D23: Salade verte
A24: Vendredi | B24: Gratin de poisson | D24: Quiche | E24: France
A25: =A20+1 -> 45673 | B25: Haricots vert | D25: Pâtess
B26: Fromage | D26: Yaourt
B27: Fruit | D27: Fruit
B28: Pamplemousse | D28: Potage de Légumes
A29: Samedi | B29: Escalope de Veau | C29: France | D29: Nugget's poulet
A30: =A25+1 -> 45674 | B30: Pomme de Terre boulangère | D30: Salsifis
B31: Fromage | D31: Yaourt
B32: Fruit | D32: Fruit
B33: Salade verte | D33: Betteraves
A34: Dimanche | B34: Paupiette de Volaille | C34: France | D34: Jambon Blanc | E34: France
A35: =A30+1 -> 45675 | B35: Riz | D35: Pomme de terre Duchesse
B36: Fromage | D36: Yaourt
B37: Dessert | D37: Fruit

Sheet semaine 4
A1: Menu du : | C1: =A5 -> 46041 | D1: AU | E1: =A35 -> 46047
B2: Midi | D2: Soir
B3: Feuilleté | D3: Salade Verte
A4: Lundi | B4: Escalope de Porc | C4: France | D4: omelette
A5: 46041 | B5: Petit Pois/Carotte | D5: Pomme de terre sautées
B6: Fromage | D6: Yaourt
B7: Fruit | D7: Fruit
B8: Salade de Chou Chinois | D8: Potage de Légumes
A9: Mardi | B9: Steack de bœuf | D9: roti de dinde | E9: France
A10: =A5+1 -> 46042 | B10: Gratin dauphinois | D10: Riz
B11: Fromage | D11: Yaourt
B12: Dessert | D12: Fruit
B13: Avocat | D13: Salade de pois chiche
A14: Mercredi | B14: Tripoux | C14: Bresil | D14: Pizza
A15: =A10+1 -> 46043 | B15: Semoule | D15: Salade Verte
B16: Fromage | D16: Yaourt
B17: Fruit | D17: Fruit
B18: Salade de Riz | D18: Potage de legumes
A19: Jeudi | B19: Chou Farçi | C19: France | D19: Hachis Parmentier | E19: France
A20: =A15+1 -> 46044
B21: Fromage | D21: Yaourt
B22: Fruit | D22: Fruit
B23: rosette | D23: Salade d'Endives
A24: Vendredi | B24: Dos de Cabillaud | D24: boulettes | E24: France
A25: =A20+1 -> 46045 | B25: Fondue de Poireaux | D25: perles
B26: Fromage | D26: Yaourt
B27: Fruit | D27: Fruit
B28: celeri rémoulade | D28: Potage de Légumes
A29: Samedi | B29: Navarin | C29: France | D29: Paté de campagne | E29: France
A30: =A25+1 -> 46046 | B30: Flageolets | D30: Brocolis
B31: Fromage | D31: Yaourt
B32: Fruit | D32: Fruit
B33: feuilleté | D33: salade chou fleur
A34: Dimanche | B34: cuisse de poulet | C34: France | D34: Dos de colin Bordelaise
A35: =A30+1 -> 46047 | B35: haricots vert | D35: pomme dauphine
B36: Fromage | D36: Yaourt
B37: Dessert | D37: Fruit

Sheet semaine 5
A1: Menu du : | C1: =A6 -> 46048 | D1: AU | E1: =A35 -> 46054
B2: Midi | D2: Soir
B3: Pâté en Croûte | D3: Poireaux en Vinaigrette
A4: Lundi | B4: Rôti de Veau | C4: France | D4: Poisson Pané
B5: Chou de Bruxelles | D5: Pomme de Terre Rissolées
A6: ='semaine 4'!A35+1 -> 46048 | B6: Fromage | D6: Yaourt
B7: Fruit | D7: Fruit
B8: Salade Verte | D8: Potage de Légumes
A9: Mardi | B9: Hamburger | C9: France | D9: Aiguillettes de Poulet aux Cèpes | E9: France
A10: =A6+1 -> 46049 | B10: Frites | D10: Carottes
D11: Yaourt
B12: Dessert | D12: Fruit
B13: Pizza | D13: Salade de Lentilles
A14: Mercredi | B14: poisson | C14: France | D14: Boudin Noir | E14: France
A15: =A10+1 -> 46050 | B15: haricots Plat | D15: Pommes Caramélisées
B16: Fromage | D16: Yaourt
B17: Fruit | D17: Fruit
B18: Salade d'Endives | D18: Potage de Féculents
A19: Jeudi | B19: Cassoulet | C19: France | D19: Epinards Florentine
A20: =A15+1 -> 46051
B21: Fromage | D21: Yaourt
B22: Fruit | D22: Fruit
B23: Salade Haricots Beurre | D23: Salade Verte
A24: Vendredi | B24: Parmentier de poisson | D24: flammenkueche | E24: France
A25: =A20+1 -> 46052 | D25: macédoine
B26: Fromage | D26: Yaourt
B27: Fruit | D27: Fruit
B28: Terrine de Campagne | D28: Potage de Légumes
A29: Samedi | B29: Sauté de Dinde | C29: France | D29: jambonnette
A30: =A25+1 -> 46053 | B30: Petit Pois | D30: Rostis
B31: Fromage | D31: Yaourt
B32: Fruit | D32: Fruit
B33: Salade de Betteraves | D33: Salade Coleslow
A34: Dimanche | B34: Rosbeef | C34: France | D34: Pâtess au chorizo | E34: France
A35: =A30+1 -> 46054 | B35: Riz
B36: Fromage | D36: Yaourt
B37: Dessert | D37: Fruit

Sheet semaine 6
A1: Menu du : | C1: =A5 -> 46055 | D1: AU | E1: =A35 -> 46061
B2: Midi | D2: Soir
B3: Taboulé | D3: Salade d'Endives
A4: Lundi | B4: Paupiette de Volaille | C4: France | D4: Jambon Blanc | E4: France
A5: ='semaine 5'!A35+1 -> 46055 | B5: Gratin de Chou Fleur | D5: Pomme de Terre Rissolées
A6: 12 pers en+ | B6: Fromage | D6: Yaourt
B7: Fruit | D7: Fruit
B8: Salade verte | D8: Potage de Légumes
A9: Mardi | B9: crêpe salé | C9: France | D9: Œuf Mayonnaise | E9: France
A10: =A5+1 -> 46056 | D10: Salsifis
A11: 12 pers en+ | D11: Yaourt
B12: Crêpe sucré | D12: Fruit
B13: Salade de Lentilles | D13: Salade de Betteraves
A14: Mercredi | B14: Sauté de Veau | C14: France | D14: Andouillette | E14: France
A15: =A10+1 -> 46057 | B15: Haricot Vert | D15: Pâtess
A16: 13 pers en+ | B16: Fromage | D16: Yaourt
B17: Fruit | D17: Fruit
B18: Paté aux olives | D18: Potage de Féculents
A19: Jeudi | B19: tête de veau | C19: France | D19: Cordon Bleu | E19: France
A20: =A15+1 -> 46058 | B20: P De Terre vapeur | D20: Chou Brocolis
A21: 13 pers en+ | B21: Fromage | D21: Yaourt
B22: Fruit | D22: Fruit
B23: Avocat | D23: Terrine de Légumes
A24: Vendredi | B24: Pavé de Poisson | C24: UE | D24: Quenelle de Volailles | E24: UE
A25: =A20+1 -> 46059 | B25: Riz | D25: carottes
A26: 13 pers en+ | B26: Fromage | D26: Yaourt
B27: Fruit | D27: Fruit
B28: Salade de Pâtess | D28: Potage de Légumes
A29: Samedi | B29: roti de Porc | C29: France | D29: Lasagne au Bœuf | E29: France
A30: =A25+1 -> 46060 | B30: Chou romanesco
B31: Fromage | D31: Yaourt
B32: Fruit | D32: Fruit
B33: salade verte | D33: Carottes Rapées
A34: Dimanche | B34: Daube | C34: France | D34: Dos de Colin Meunière | E34: Alaska
A35: =A30+1 -> 46061 | B35: semoule | D35: Rapé de Pomme de Terre
B36: Fromage | D36: Yaourt
B37: Dessert | D37: Fruit

Sheet semaine 7
A1: Menu du : | C1: =A5 -> 46062 | D1: AU | E1: =A35 -> 46068
B2: Midi | D2: Soir
B3: Salade verte | D3: Salade de Perles
A4: Lundi | B4: Sauté de Lapin | C4: France | D4: Endives au Jambon | E4: France
A5: ='semaine 6'!A35+1 -> 46062 | B5: Choux de Bruxelles
B6: Fromage | D6: Yaourt
B7: Fruit | D7: Fruit
B8: Salade Coleslow | D8: Potage de Légumes
A9: Mardi | B9: Croziflette | C9: France | D9: Chipolatas | E9: France
A10: =A5+1 -> 46063 | D10: Haricots blanc
D11: Yaourt
B12: Dessert | D12: Fruit
B13: Taboulé | D13: Macédoine de Légumes
A14: Mercredi | B14: Escalope dinde | C14: France | D14: Raviolis | E14: France
A15: =A10+1 -> 46064 | B15: gratin de potimarron
B16: Fromage | D16: Yaourt
B17: Fruit | D17: Fruit
B18: Salade de Chou Chinois | D18: Potage de Féculents
A19: Jeudi | B19: Saucisse | C19: France | D19: Œuf béchamel
A20: =A15+1 -> 46065 | B20: Aligot | D20: Haricots beurre
A21: 2 pers en+ | D21: Yaourt
B22: Fruit | D22: Fruit
B23: Mousse de Canard | D23: Salade d'endives
A24: Vendredi | B24: Saumon | D24: Chili con carne | E24: France
A25: =A20+1 -> 46066 | B25: Chou Romanesco
B26: Fromage | D26: Yaourt
B27: Fruit | D27: Fruit
B28: Carottes Rapées | D28: Potage de Légumes
A29: Samedi | B29: Flecque | C29: France | D29: Pates Carbonara | E29: France
A30: =A25+1 -> 46067
B31: Fromage | D31: Yaourt
B32: Fruit | D32: Fruit
B33: Salade verte | D33: Salade de Riz
A34: Dimanche | B34: Rôti de Veau | C34: France | D34: maquereaux
A35: =A30+1 -> 46068 | B35: Lentilles | D35: Poelée de légumes
B36: Fromage | D36: Yaourt
B37: Dessert | D37: Fruit

Sheet semaine 8
A1: Menu du : | C1: =A5 -> 46069 | D1: AU | E1: =A35 -> 46075
B2: Midi | D2: Soir
B3: Tranche de Jambon Cru | D3: Poireaux vinaigrette
A4: Lundi | B4: Pavé de Poisson | D4: Escalope viennoise | E4: France
A5: ='semaine 7'!A35+1 -> 46069 | B5: Epinards à la crème | D5: Riz
B6: Fromage | D6: Yaourt
B7: Fruit | D7: Fruit
B8: Avocat | D8: Potage de Légumes
A9: Mardi | B9: Pot au feu | C9: France | D9: Pâtess Bolognaise
A10: =A5+1 -> 46070
B11: Fromage | D11: Yaourt
B12: Dessert | D12: Fruit
B13: Feuilleté | D13: Taboulé
A14: Mercredi | B14: Sûprèmes de Volaille | C14: France | D14: Langue de Bœuf Sauce Piquante | E14: Brésil
A15: =A10+1 -> 46071 | B15: Petit Pois | D15: Côtes de Blette
B16: Fromage | D16: Yaourt
B17: Fruit | D17: Fruit
B18: Salade d'Endives | D18: Potage de Féculents
A19: Jeudi | B19: Choucroute | C19: France | D19: Mortadelle | E19: France
A20: =A15+1 -> 46072 | D20: Carottes Persillées
B21: Fromage | D21: Yaourt
B22: Fruit | D22: Fruit
B23: Salade Mexicaine | D23: Salade verte
A24: Vendredi | B24: Gratin de poisson | D24: Quiche | E24: France
A25: =A20+1 -> 46073 | B25: Haricots vert | D25: Pâtess
B26: Fromage | D26: Yaourt
B27: Fruit | D27: Fruit
B28: Pamplemousse | D28: Potage de Légumes
A29: Samedi | B29: Escalope de Veau | C29: France | D29: Nugget's poulet
A30: =A25+1 -> 46074 | B30: Pomme de Terre boulangère | D30: Salsifis
B31: Fromage | D31: Yaourt
B32: Fruit | D32: Fruit
B33: Salade verte | D33: Betteraves
A34: Dimanche | B34: Paupiette de Veau | C34: France | D34: Jambon Blanc | E34: France
A35: =A30+1 -> 46075 | B35: Riz | D35: rosti
B36: Fromage | D36: Yaourt
B37: Dessert | D37: Fruit

Sheet semaine 9 
A1: Menu du : | C1: =A5 -> 46076 | D1: AU | E1: =A35 -> 46082
B2: Midi | D2: Soir
B3: Feuilleté | D3: Salade Verte
A4: Lundi | B4: Escalope de Porc | C4: France | D4: Lasagne
A5: ='semaine 8'!A35+1 -> 46076 | B5: Petit Pois/Carotte
B6: Fromage | D6: Yaourt
B7: Fruit | D7: Fruit
B8: Salade de betteraves | D8: Potage de Légumes
A9: Mardi | B9: Steack de bœuf | D9: roti de dinde | E9: France
A10: =A5+1 -> 46077 | B10: Gratin dauphinois | D10: Riz
B11: Fromage | D11: Yaourt
B12: Dessert | D12: Fruit
B13: Terrine de légumes | D13: Salade de pois chiche
A14: Mercredi | B14: Tripoux | C14: Bresil | D14: Pizza
A15: =A10+1 -> 46078 | B15: Semoule | D15: Salade Verte
B16: Fromage | D16: Yaourt
B17: Fruit | D17: Fruit
B18: Salade de Riz | D18: Potage de legumes
A19: Jeudi | B19: Chou Farçi | C19: France | D19: Hachis Parmentier | E19: France
A20: =A15+1 -> 46079
B21: Fromage | D21: Yaourt
B22: Fruit | D22: Fruit
B23: rosette | D23: Carottes râpées
A24: Vendredi | B24: Dos de Cabillaud | D24: boulettes | E24: France
A25: =A20+1 -> 46080 | B25: Fondue de Poireaux | D25: perles
B26: Fromage | D26: Yaourt
B27: Fruit | D27: Fruit
B28: Celeri rémoulade | D28: Potage de Légumes
A29: Samedi | B29: Saucisses | C29: France | D29: Paté de campagne | E29: France
A30: =A25+1 -> 46081 | B30: Flageolets | D30: Brocolis
B31: Fromage | D31: Yaourt
B32: Fruit | D32: Fruit
B33: feuilleté | D33: salade chou fleur
A34: Dimanche | B34: cuisse de poulet | C34: France | D34: Dos de colin Bordelaise
A35: =A30+1 -> 46082 | B35: haricots vert | D35: pomme dauphine
B36: Fromage | D36: Yaourt
B37: Dessert | D37: Fruit

Sheet semaine 10
A1: Menu du : | C1: =A5 -> 46083 | D1: AU | E1: =A35 -> 46089
B2: Midi | D2: Soir
B3: Pâté en Croûte | D3: Poireaux en Vinaigrette
A4: Lundi | B4: Rôti de Veau | C4: France | D4: Poisson Pané
A5: ='semaine 9 '!A35+1 -> 46083 | B5: Chou de Bruxelles | D5: Pomme de Terre sauté
B6: Fromage | D6: Yaourt
B7: Fruit | D7: Fruit
B8: Salade Verte | D8: Potage de Légumes
A9: Mardi | B9: Hamburger | C9: France | D9: Aiguillettes de Poulet aux Cèpes | E9: France
A10: =A5+1 -> 46084 | B10: Frites | D10: Carottes
D11: Yaourt
B12: Dessert | D12: Fruit
B13: Pizza | D13: Salade de Lentilles
A14: Mercredi | B14: poisson | C14: France | D14: Boudin Noir | E14: France
A15: =A10+1 -> 46085 | B15: haricots Plat | D15: Pommes Caramélisées
B16: Fromage | D16: Yaourt
B17: Fruit | D17: Fruit
B18: Salade d'Endives | D18: Potage de Féculents
A19: Jeudi | B19: Cassoulet | C19: France | D19: Epinards Florentine
A20: =A15+1 -> 46086
A21: 16 pers en+ | B21: Fromage | D21: Yaourt
B22: Fruit | D22: Fruit
B23: Salade Haricots Beurre | D23: Salade Verte
A24: Vendredi | B24: Parmentier de poisson | D24: flammenkueche | E24: France
A25: =A20+1 -> 46087 | D25: macédoine
B26: Fromage | D26: Yaourt
B27: Fruit | D27: Fruit
B28: Terrine de Campagne | D28: Potage de Légumes
A29: Samedi | B29: Sauté de Dinde | C29: France | D29: jambonnette
A30: =A25+1 -> 46088 | B30: Petit Pois | D30: Rostis
B31: Fromage | D31: Yaourt
B32: Fruit | D32: Fruit
B33: Salade de Betteraves | D33: Salade Coleslow
A34: Dimanche | B34: Rosbeef | C34: France | D34: Pâtess au chorizo | E34: France
A35: =A30+1 -> 46089 | B35: Riz
B36: Fromage | D36: Yaourt
B37: Dessert | D37: Fruit

Sheet semaine 11
A1: Menu du : | C1: =A6 -> 46090 | D1: AU | E1: =A35 -> 46096
B2: Midi | D2: Soir
B3: Taboulé | D3: Salade d'Endives
A4: Lundi | B4: Paupiette de Volaille | C4: France | D4: Jambon Blanc | E4: France
B5: Gratin de Chou Fleur | D5: Pomme de Terre Rissolées
A6: ='semaine 10'!A35+1 -> 46090 | B6: Fromage | D6: Yaourt
A7: 13 pers en+ | B7: Fruit | D7: Fruit
B8: Pamplemousse | D8: Potage de Légumes
A9: Mardi | B9: Tartiflette | C9: France | D9: Œuf Mayonnaise | E9: France
A10: =A6+1 -> 46091 | D10: Salsifis
D11: Yaourt
A12: 13 pers en+ | B12: Dessert | D12: Fruit
B13: Salade de Lentilles | D13: Salade de Betteraves
A14: Mercredi | B14: Sauté de Veau | C14: France | D14: Andouillette | E14: France
A15: =A10+1 -> 46092 | B15: Haricot Vert | D15: Pâtess
B16: Fromage | D16: Yaourt
A17: 13 pers en+ | B17: Fruit | D17: Fruit
B18: Avocat Mayonnaise | D18: Potage de Féculents
A19: Jeudi | B19: tête de veau | C19: France | D19: Cordon Bleu | E19: France
A20: =A15+1 -> 46093 | B20: P De Terre vapeur | D20: Chou Brocolis
B21: Fromage | D21: Yaourt
B22: Fruit | D22: Fruit
B23: Paté aux olives | D23: Terrine de Légumes
A24: Vendredi | B24: Pavé de Poisson | C24: UE | D24: Quenelle de Volailles | E24: UE
A25: =A20+1 -> 46094 | B25: Riz | D25: carottes
B26: Fromage | D26: Yaourt
B27: Fruit | D27: Fruit
B28: Salade de Pâtess | D28: Potage de Légumes
A29: Samedi | B29: roti de Porc | C29: France | D29: Lasagne au Bœuf | E29: France
A30: =A25+1 -> 46095 | B30: Chou romanesco
B31: Fromage | D31: Yaourt
B32: Fruit | D32: Fruit
B33: salade verte | D33: Carottes Rapées
A34: Dimanche | B34: Daube | C34: France | D34: Dos de Colin Meunière | E34: Alaska
A35: =A30+1 -> 46096 | B35: semoule | D35: Rapé de Pomme de Terre
B36: Fromage | D36: Yaourt
B37: Dessert | D37: Fruit

Sheet semaine 12
A1: Menu du : | C1: =A5 -> 46097 | D1: AU | E1: =A35 -> 46103
B2: Midi | D2: Soir
B3: Salade verte | D3: Salade de Perles
A4: Lundi | B4: Sauté de Lapin | C4: France | D4: Endives au Jambon | E4: France
A5: ='semaine 11'!A35+1 -> 46097 | B5: Choux de Bruxelles
B6: Fromage | D6: Yaourt
B7: Fruit | D7: Fruit
B8: Salade Coleslow | D8: Potage de Légumes
A9: Mardi | B9: Croziflette | C9: France | D9: Chipolatas | E9: France
A10: =A5+1 -> 46098 | D10: Haricots blanc
D11: Yaourt
B12: Dessert | D12: Fruit
B13: Taboulé | D13: Macédoine de Légumes
A14: Mercredi | B14: Escalope dinde | C14: France | D14: Raviolis | E14: France
A15: =A10+1 -> 46099 | B15: gratin de potimarron
B16: Fromage | D16: Yaourt
B17: Fruit | D17: Fruit
B18: Salade de Chou Chinois | D18: Potage de Féculents
A19: Jeudi | B19: Saucisse | C19: France | D19: Œuf béchamel
A20: =A15+1 -> 46100 | B20: Aligot | D20: Haricots beurre
D21: Yaourt
B22: Fruit | D22: Fruit
B23: Mousse de Canard | D23: Salade d'endives
A24: Vendredi | B24: Saumon | D24: Chili con carne | E24: France
A25: =A20+1 -> 46101 | B25: Chou Romanesco
B26: Fromage | D26: Yaourt
B27: Fruit | D27: Fruit
B28: Carottes Rapées | D28: Potage de Légumes
A29: Samedi | B29: Flecque | C29: France | D29: Pates Carbonara | E29: France
A30: =A25+1 -> 46102
B31: Fromage | D31: Yaourt
B32: Fruit | D32: Fruit
B33: Salade verte | D33: Salade de Riz
A34: Dimanche | B34: Rôti de Veau | C34: France | D34: maquereaux
A35: =A30+1 -> 46103 | B35: Lentilles | D35: Poelée de légumes
B36: Fromage | D36: Yaourt
B37: Dessert | D37: Fruit

Sheet semaine 13
A1: Menu du : | C1: =A5 -> 46104 | D1: AU | E1: =A35 -> 46110
B2: Midi | D2: Soir
B3: Tranche de Jambon Cru | D3: Poireaux vinaigrette
A4: Lundi | B4: Pavé de Poisson | D4: Escalope viennoise | E4: France
A5: ='semaine 12'!A35+1 -> 46104 | B5: Epinards à la crème | D5: Riz
B6: Fromage | D6: Yaourt
B7: Fruit | D7: Fruit
B8: Avocat | D8: Potage de Légumes
A9: Mardi | B9: Pot au feu | C9: France | D9: Pâtess Bolognaise
A10: =A5+1 -> 46105
B11: Fromage | D11: Yaourt
B12: Dessert | D12: Fruit
B13: Feuilleté | D13: Taboulé
A14: Mercredi | B14: Sûprèmes de Volaille | C14: France | D14: Langue de Bœuf Sauce Piquante | E14: Brésil
A15: =A10+1 -> 46106 | B15: Petit Pois | D15: Côtes de Blette
B16: Fromage | D16: Yaourt
B17: Fruit | D17: Fruit
B18: Salade d'Endives | D18: Potage de Féculents
A19: Jeudi | B19: Choucroute | C19: France | D19: Mortadelle | E19: France
A20: =A15+1 -> 46107 | D20: Carottes Persillées
B21: Fromage | D21: Yaourt
A22: 13 pers en+ | B22: Fruit | D22: Fruit
B23: Salade Mexicaine | D23: Salade verte
A24: Vendredi | B24: Gratin de poisson | D24: Quiche | E24: France
A25: =A20+1 -> 46108 | B25: Haricots vert | D25: Pâtess
B26: Fromage | D26: Yaourt
B27: Fruit | D27: Fruit
B28: Pamplemousse | D28: Potage de Légumes
A29: Samedi | B29: Escalope de Veau | C29: France | D29: Nugget's poulet
A30: =A25+1 -> 46109 | B30: Pomme de Terre boulangère | D30: Salsifis
B31: Fromage | D31: Yaourt
B32: Fruit | D32: Fruit
B33: Salade verte | D33: Betteraves
A34: Dimanche | B34: Paupiette de Volaille | C34: France | D34: Jambon Blanc | E34: France
A35: =A30+1 -> 46110 | B35: Riz | D35: Pomme de terre Duchesse
B36: Fromage | D36: Yaourt
B37: Dessert | D37: Fruit

Sheet semaine 14
A1: Menu du : | C1: =A6 -> 46111 | D1: AU | E1: =A35 -> 46117
B2: Midi | D2: Soir
B3: Feuilleté | D3: Salade Verte
A4: Lundi | B4: Escalope de Porc | C4: France | D4: omelette
B5: Petit Pois/Carotte | D5: Pomme de terre sautées
A6: ='semaine 13'!A35+1 -> 46111 | B6: Fromage | D6: Yaourt ou Fromage
B7: Fruit | D7: Fruit Cuit
B8: Salade de Chou Chinois | D8: Potage de Légumes
A9: Mardi | B9: Steack de bœuf | D9: roti de dinde | E9: France
A10: =A6+1 -> 46112 | B10: Gratin dauphinois | D10: Riz
B11: Fromage | D11: Yaourt ou Fromage
B12: Dessert | D12: Fruit
B13: Avocat | D13: Salade de pois chiche
A14: Mercredi | B14: Tripoux | C14: Bresil | D14: Pizza
A15: =A10+1 -> 46113 | B15: Semoule | D15: Salade Verte
B16: Fromage | D16: Yaourt ou Fromage
B17: Fruit Cuit | D17: Fruit Cuit
B18: Salade de Riz | D18: Potage de legumes
A19: Jeudi | B19: Chou Farçi | C19: France | D19: Hachis Parmentier | E19: France
A20: =A15+1 -> 46114
B21: Fromage | D21: Yaourt ou Fromage
B22: Fruit | D22: Fruit
B23: rosette | D23: Salade d'Endives
A24: Vendredi | B24: Dos de Cabillaud | D24: boulettes | E24: France
A25: =A20+1 -> 46115 | B25: Fondue de Poireaux | D25: perles
B26: Fromage | D26: Yaourt ou Fromage
B27: Fruit | D27: Fruit Cuit
B28: celeri rémoulade | D28: Potage de Légumes
A29: Samedi | B29: Navarin | C29: France | D29: Paté de campagne | E29: France
A30: =A25+1 -> 46116 | B30: Flageolets | D30: Brocolis
B31: Fromage | D31: Yaourt ou Fromage
B32: Fruit | D32: Fruit
B33: feuilleté | D33: salade chou fleur
A34: Dimanche | B34: cuisse de poulet | C34: France | D34: Dos de colin Bordelaise
A35: =A30+1 -> 46117 | B35: haricots vert | D35: pomme dauphine
B36: Fromage | D36: Yaourt ou Fromage
B37: Dessert | D37: Fruit

Sheet semaine 15
A1: Menu du : | C1: =A5 -> 46118 | D1: AU | E1: =A35 -> 46124
B2: Midi | D2: Soir
B3: Saucisse sèche
A4: Lundi | B4: Tournedos | C4: France | D4: Salade de pâtes composé | E4: France
A5: ='semaine 14'!A35+1 -> 46118 | B5: Purée patate douce
B6: Fromage | D6: Laitage
B7: Dessert | D7: Fruit
B8: Betteraves | D8: Salade verte
A9: Mardi | B9: Calamar | C9: France | D9: Croque monsieur | E9: France
A10: =A5+1 -> 46119 | B10: Riz
B11: Fromage | D11: Laitage
B12: Dessert | D12: Fruit
B13: Salade pomme de terre | D13: Macédoine
A14: Mercredi | B14: Rôti de veau | C14: France | D14: Jambon braiser | E14: France
A15: =A10+1 -> 46120 | B15: Flan de légume | D15: rösti
B16: Fromage | D16: Laitage
B17: Fruit | D17: Fruit
B18: Carottes Rapée | D18: Salade de pois chiche
A19: Jeudi | B19: Bourguignon | C19: France | D19: Carbonade artichaud | E19: France
A20: =A15+1 -> 46121 | B20: Pâtes
B21: Fromage | D21: Laitage
B22: Fruit | D22: Fruit
B23: Taboulé | D23: Salade verte
A24: Vendredi | B24: Poisson | C24: France | D24: Quiche | E24: France
A25: =A20+1 -> 46122 | B25: Jardinière de légumes
B26: Fromage | D26: Laitage
B27: Fruit | D27: Fruit
B28: Betteraves | D28: Feuilleté
A29: Samedi | B29: Rosbeef | C29: France | D29: Moussaka | E29: France
A30: =A25+1 -> 46123 | B30: Gnocchi
B31: Fromage | D31: Laitage
B32: Fruit | D32: Fruit
B33: Crêpe | D33: Salade verte
A34: Dimanche | B34: Petite salée | C34: France | D34: Brandade de morue | E34: France
A35: =A30+1 -> 46124 | B35: Lentilles
B36: Fromage | D36: Laitage
B37: Dessert | D37: Fruit

Sheet semaine 16
A1: Menu du : | C1: =A5 -> 46125 | D1: AU | E1: =A35 -> 46131
B2: Midi | D2: Soir
B3: Salade mexicaine | D3: Salade de tomates
A4: Lundi | B4: Cuisse de lapin | C4: France | D4: Cordon bleu | E4: France
A5: ='semaine 15'!A35+1 -> 46125 | B5: salsifis | D5: Pates
B6: Fromage | D6: Laitage
B7: Fruit | D7: Fruit
B8: Salade verte | D8: Salade de riz
A9: Mardi | B9: Tête de veau | C9: France | D9: Omelette | E9: France
A10: =A5+1 -> 46126 | B10: Pomme de terre | D10: Haricots beurre
B11: Fromage | D11: Laitage
B12: Dessert | D12: Fruit
B13: Pizza | D13: Asperge
A14: Mercredi | B14: Rôti de porc | C14: France | D14: Merguez | E14: France
A15: =A10+1 -> 46127 | B15: Carotte | D15: Semoule
B16: Fromage | D16: Laitage
B17: Fruit | D17: Fruit
B18: Râpé de courgette | D18: Salade de lentilles
A19: Jeudi | B19: Steak de bœuf | C19: France | D19: Quenelle | E19: France
A20: =A15+1 -> 46128 | B20: Gratin dauphinois | D20: Brocolis
B21: Fromage | D21: Laitage
B22: Fruit | D22: Fruit
B23: Rillettes de canard | D23: Salade verte
A24: Vendredi | B24: Lasagne saumon épinard | C24: France | D24: Jambon a la russe | E24: France
A25: =A20+1 -> 46129
B26: Fromage | D26: Laitage
B27: Fruit | D27: Fruit
B28: Salade de choux fleur | D28: Salade pois chiche
A29: Samedi | B29: Poulet basquaise | C29: France | E29: France
A30: =A25+1 -> 46130 | B30: Riz | D30: Rosbeef froid
B31: Fromage | D31: Laitage
B32: Fruit | D32: Fruit
B33: Salade de pate | D33: Terrine de légumes
A34: Dimanche | B34: Escalope de porc | C34: France | D34: Bouché a la reine | E34: France
A35: =A30+1 -> 46131 | B35: Flan de blette
B36: Fromage | D36: Laitage
B37: Dessert | D37: Fruit

Sheet semaine 17
A1: Menu du : | C1: =A5 -> 46132 | D1: AU | E1: =A35 -> 46138
B2: Midi | D2: Soir
B3: Taboulé | D3: Salade haricots vert
A4: Lundi | B4: Rôti de porc | C4: France | D4: Poisson pané | E4: France
A5: ='semaine 16'!A35+1 -> 46132 | B5: Choux brocolis | D5: Pomme de terre rissolé
B6: Fromage | D6: Laitage
B7: Fruit | D7: Fruit
B8: salade verte | D8: Feuilleté
A9: Mardi | B9: Paëlla | C9: France | D9: Jambon picard | E9: France
A10: =A5+1 -> 46133
B11: Fromage | D11: Laitage
B12: Dessert | D12: Fruit
B13: Salade de pomme de terre | D13: Carotte râpé
A14: Mercredi | B14: Steak haché | C14: France | D14: Chipolata | E14: France
A15: =A10+1 -> 46134 | B15: Tomate provençal | D15: Lentille
B16: Fromage | D16: Laitage
B17: Fruit | D17: Fruit
B18: Avocat | D18: Tarte à la tomate et chèvre
A19: Jeudi | B19: Sauté de veau | C19: France | D19: Nuggets | E19: France
A20: =A15+1 -> 46135 | B20: Riz | D20: Poêle campagnarde
B21: Fromage | D21: Laitage
B22: Fruit | D22: Fruit
B23: Salade mexicaine | D23: Céleri rémoulade
A24: Vendredi | B24: Blanquette de poisson | C24: France | D24: Boulette de bœuf | E24: France
A25: =A20+1 -> 46136 | B25: Fondu de poireaux | D25: Semoule
B26: Fromage | D26: Laitage
B27: Fruit | D27: Fruit
B28: Salade de betterave-maïs | D28: Salade de pate
A29: Samedi | B29: Escalope de veau | C29: France | D29: Tomate farcie | E29: France
A30: =A25+1 -> 46137 | B30: Pomme de terre vapeur
B31: Fromage | D31: Laitage
B32: Fruit | D32: Fruit
B33: Rosette | D33: Salade césar
A34: Dimanche | B34: Navarin agneau | C34: France | D34: Crêpe au champignon | E34: France
A35: =A30+1 -> 46138 | B35: Flageolet
B36: Fromage | D36: Laitage
B37: Dessert | D37: Fruit

Sheet semaine 18
A1: Menu du : | C1: =A5 -> 46139 | D1: AU | E1: =A35 -> 46145
B2: Midi | D2: Soir
B3: Salade de riz | D3: Macédoine de légume
A4: Lundi | B4: Blanc de poulet | C4: France | D4: Chipolata | E4: France
A5: ='semaine 17'!A35+1 -> 46139 | B5: Haricots plat | D5: Lentille
B6: Fromage | D6: Laitage
B7: Fruit | D7: Fruit
B8: Salade verte | D8: Poireaux
A9: Mardi | B9: Hamburger | C9: France | D9: Poisson pané | E9: France
A10: =A5+1 -> 46140 | B10: Frite | D10: Carotte
D11: Laitage
B12: Dessert | D12: Fruit
B13: Salade pois chiche | D13: Choux rouge
A14: Mercredi | B14: Rôti de veau | C14: France | D14: Trippes | E14: France
A15: =A10+1 -> 46141 | B15: Tomate provençal | D15: Pomme de terre
B16: Fromage | D16: Laitage
B17: Fruit | D17: Fruit
B18: Asperge | D18: Oeuf mayo
A19: Jeudi | B19: Sot l'y laisse de dinde | C19: France | D19: Gratin de courgette a la viande | E19: France
A20: =A15+1 -> 46142 | B20: Pâtes
B21: Fromage | D21: Laitage
B22: Fruit | D22: Fruit
B23: Rillettes de canard | D23: Salade mexicaine
A24: Vendredi | B24: Filet de dorade | C24: France | D24: Escalope de volaille | E24: France
A25: =A20+1 -> 46143 | B25: riz | D25: Haricots verts
B26: Fromage | D26: Laitage
B27: Dessert | D27: Fruit
B28: Salade de tomate | D28: Salade verte
A29: Samedi | B29: Escalope de porc | C29: France | D29: Bouché a la reine | E29: France
A30: =A25+1 -> 46144 | B30: Choux brocolis
B31: Fromage | D31: Laitage
B32: Fruit | D32: Fruit
B33: Taboulé | D33: Salade de betterave
A34: Dimanche | B34: Rosbeef | C34: France | D34: Gratin de pate au jambon | E34: France
A35: =A30+1 -> 46145 | B35: Flan blette
B36: Fromage | D36: Laitage
B37: Dessert | D37: Fruit

Sheet semaine 19
A1: Menu du : | C1: =A5 -> 46146 | D1: AU | E1: =A35 -> 46152
B2: Midi | D2: Soir
B3: Surimi | D3: Salade de lentille
A4: Lundi | B4: Paupiette de volaille | C4: France | D4: Saucisson brioché | E4: France
A5: ='semaine 18'!A35+1 -> 46146 | B5: salsifis
B6: Fromage | D6: Laitage
B7: Fruit | D7: Fruit
B8: Tomates mozzarella | D8: Salade de pâtes
A9: Mardi | B9: Couscous et | C9: France | D9: Endive au jambon | E9: France
A10: =A5+1 -> 46147 | B10: ses légumes
D11: Laitage
B12: Dessert | D12: Fruit
B13: Salade verte | D13: Cèleri rémoulade
A14: Mercredi | B14: Steak de bœuf | C14: France | D14: Poisson bordelaise | E14: France
A15: =A10+1 -> 46148 | B15: Pommes de terre sautées | D15: Haricots verts
B16: Fromage | D16: Laitage
B17: Fruit | D17: Fruit
B18: Avocat | D18: Salade ebly
A19: Jeudi | B19: Rougail saucisse | C19: France | D19: Epinard a la florentine | E19: France
A20: =A15+1 -> 46149 | B20: riz
B21: Fromage | D21: Laitage
B22: Fruit | D22: Fruit
B23: Terrine tomate mozzarella basilic | D23: Salade composé
A24: Vendredi | B24: Dos de loup | C24: France | D24: Tarte méditerranéenne | E24: France
A25: =A20+1 -> 46150 | B25: Ratatouille
B26: Fromage | D26: Laitage
B27: Dessert | D27: Fruit
B28: Asperge | D28: Taboulé
A29: Samedi | B29: Filet mignon de porc | C29: France | D29: donuts poulet | E29: France
A30: =A25+1 -> 46151 | B30: Pâtes | D30: Poêle de légumes
B31: Fromage | D31: Laitage
B32: Fruit | D32: Fruit
B33: Coquille saint jacques | D33: Salade verte
A34: Dimanche | B34: Hachis Parmentier de canard | C34: France | D34: cassoulet | E34: France
A35: =A30+1 -> 46152
B36: Fromage | D36: Laitage
B37: Dessert | D37: Fruit

Sheet semaine 20
A1: Menu du : | C1: =A6 -> 46153 | D1: AU | E1: =A35 -> 46159
B2: Midi | D2: Soir
B3: saucisse sèche
A4: Lundi | B4: escalope de porc | C4: France | D4: Salade de pâtes composé | E4: France
B5: Haricots vert | D5: Roti de dinde
A6: ='semaine 19'!A35+1 -> 46153 | B6: fromage | D6: Laitage
B7: fruit | D7: Fruit
B8: Betteraves | D8: Salade verte
A9: Mardi | B9: Calamar | C9: France | D9: Croque monsieur | E9: France
A10: =A6+1 -> 46154 | B10: Riz
B11: Fromage | D11: Laitage
B12: Fraise | D12: Fruit
B13: Salade pomme de terre | D13: Macédoine
A14: Mercredi | B14: Rôti de veau | C14: France | D14: Jambon braiser | E14: France
A15: =A10+1 -> 46155 | B15: Flan de légume | D15: rösti
B16: Fromage | D16: Laitage
B17: Fruit | D17: Fruit
B18: Carottes Rapée | D18: Salade de pois chiche
A19: Jeudi | B19: Bourguignon | C19: France | D19: Carbonade artichaud | E19: France
A20: =A15+1 -> 46156 | B20: Pâtes
B21: Fromage | D21: Laitage
B22: Dessert | D22: Fruit
B23: Taboulé | D23: Salade verte
A24: Vendredi | B24: Poisson | C24: France | D24: Quiche | E24: France
A25: =A20+1 -> 46157 | B25: Jardinière de légumes
B26: Fromage | D26: Laitage
B27: Fruit | D27: Fruit
B28: Betteraves | D28: Feuilleté
A29: Samedi | B29: Rosbeef | C29: France | D29: Moussaka | E29: France
A30: =A25+1 -> 46158 | B30: Gnocchi
B31: Fromage | D31: Laitage
B32: Fruit | D32: Fruit
B33: Crêpe | D33: Salade verte
A34: Dimanche | B34: Petite salée | C34: France | D34: Brandade de morue | E34: France
A35: =A30+1 -> 46159 | B35: Lentilles
B36: Fromage | D36: Laitage
B37: Dessert | D37: Fruit

Sheet semaine 21
A1: Menu du : | C1: =A5 -> 46160 | D1: AU | E1: =A35 -> 46166
B2: Midi | D2: Soir
B3: Salade mexicaine | D3: Salade de tomates
A4: Lundi | B4: Sauté de lapin | C4: France | D4: Cordon bleu | E4: France
A5: ='semaine 20'!A35+1 -> 46160 | B5: salsifis | D5: Pates
B6: Fromage | D6: Laitage
B7: Fruit | D7: Fruit
B8: Salade verte | D8: Salade de riz
A9: Mardi | B9: Tête de veau | C9: France | D9: Poisson pané | E9: France
A10: =A5+1 -> 46161 | B10: Pomme de terre | D10: Haricots beurre
B11: Fromage | D11: Laitage
B12: Dessert | D12: Fruit
B13: Feuilleté | D13: macédoine
A14: Mercredi | B14: Rôti de porc | C14: France | D14: Merguez | E14: France
A15: =A10+1 -> 46162 | B15: Carotte | D15: Semoule
B16: Fromage | D16: Laitage
B17: Fruit | D17: Fruit
B18: Salade de choux fleur | D18: Salade de lentilles
A19: Jeudi | B19: Steak de bœuf | C19: France | D19: courgette farcie | E19: France
A20: =A15+1 -> 46163 | B20: Gratin dauphinois
B21: Fromage | D21: Laitage
B22: Fruit | D22: Fruit
B23: panseta | D23: Salade verte
A24: Vendredi | B24: Lasagne saumon épinard | C24: France | D24: croque monsieur | E24: France
A25: =A20+1 -> 46164
B26: Fromage | D26: Laitage
B27: Fruit | D27: Fruit
B28: Râpé de courgette | D28: Salade pois chiche
A29: Samedi | B29: Poulet basquaise | C29: France | E29: France
A30: =A25+1 -> 46165 | B30: Riz | D30: Rosbeef froid
B31: Fromage | D31: Laitage
B32: Fruit | D32: Fruit
B33: betterave | D33: Terrine de légumes
A34: Dimanche | B34: Escalope de veau | C34: France | D34: Bouché a la reine | E34: France
A35: =A30+1 -> 46166 | B35: rostie
B36: Fromage | D36: Laitage
B37: Dessert | D37: Fruit

Sheet semaine 22
A1: Menu du : | C1: =A5 -> 46167 | D1: AU | E1: =A35 -> 46173
B2: Midi | D2: Soir
B3: coquille saint jacques | D3: Salade haricots vert
A4: Lundi | B4: supreme de vollaile | C4: France | D4: Poisson pané | E4: France
A5: ='semaine 21'!A35+1 -> 46167 | B5: perle
B6: Fromage | D6: Laitage
B7: Fruit | D7: Fruit
B8: salade verte | D8: Feuilleté
A9: Mardi | B9: Paëlla | C9: France | D9: Jambon picard | E9: France
A10: =A5+1 -> 46168
B11: Fromage | D11: Laitage
B12: Dessert | D12: Fruit
B13: Salade de pomme de terre | D13: Carotte râpé
A14: Mercredi | B14: Steak haché | C14: France | D14: Chipolata | E14: France
A15: =A10+1 -> 46169 | B15: Tomate provençal | D15: Lentille
B16: Fromage | D16: Laitage
B17: Fruit | D17: Fruit
B18: Avocat | D18: Tarte meditéraenne
A19: Jeudi | B19: Sauté de veau | C19: France | D19: Nuggets | E19: France
A20: =A15+1 -> 46170 | B20: Riz | D20: Poêle campagnarde
B21: Fromage | D21: Laitage
B22: Fruit | D22: Fruit
B23: Salade mexicaine | D23: Céleri rémoulade
A24: Vendredi | B24: poisson | C24: France | D24: croque monsieur ou bouché a la reine | E24: France
A25: =A20+1 -> 46171 | B25: Semoule
B26: Fromage | D26: Laitage
B27: Fruit | D27: Fruit
B28: Salade de betterave-maïs | D28: Salade de tomate
A29: Samedi | B29: cordon bleu | C29: France | D29: boulette de bœuf | E29: France
A30: =A25+1 -> 46172 | B30: gratin d'auphinois | D30: carotte
B31: Fromage | D31: Laitage
B32: Fruit | D32: Fruit
B33: Rosette | D33: Salade
A34: Dimanche | B34: roti de porc | C34: France | D34: Crêpe | E34: France
A35: =A30+1 -> 46173 | B35: Flageolet
B36: Fromage | D36: Laitage
B37: Dessert | D37: Fruit

Sheet semaine 23
A1: Menu du : | C1: =A5 -> 46174 | D1: AU | E1: =A35 -> 46180
B2: Midi | D2: Soir
B3: Salade de riz | D3: Macédoine de légume
A4: Lundi | B4: Blanc de poulet | C4: France | D4: Chipolata | E4: France
A5: ='semaine 22'!A35+1 -> 46174 | B5: Haricots plat | D5: Lentille
B6: Fromage | D6: Laitage
B7: Fruit | D7: Fruit
B8: Salade verte | D8: Feuilleté
A9: Mardi | B9: blanquette de veau | C9: France | D9: Poisson pané | E9: France
A10: =A5+1 -> 46175 | B10: pate | D10: Carotte
D11: Laitage
B12: Dessert | D12: Fruit
B13: Salade pois chiche | D13: salade haricots vert
A14: Mercredi | B14: steack | C14: France | D14: Trippes | E14: France
A15: =A10+1 -> 46176 | B15: Tomate provençal | D15: pomme de terre vapeur
B16: Fromage | D16: Laitage
B17: Fruit | D17: Fruit
B18: Asperge | D18: Sardine
A19: Jeudi | B19: Escalope de veau | C19: France | D19: courgette farcie | E19: France
A20: =A15+1 -> 46177 | B20: pomme dauphine
B21: Fromage | D21: Laitage
B22: Fruit | D22: Fruit
B23: mache accompagné tartine chévre | D23: Salade mexicaine
A24: Vendredi | B24: sourie agneaux | C24: France | D24: donut poulet | E24: France
A25: =A20+1 -> 46178 | B25: pomme de terre grenaille | D25: Haricots beurre
A26: Fêtes famille | B26: Fromage | D26: Laitage
B27: cheesecake mangue | D27: Fruit
B28: Salade de tomate | D28: Salade verte
A29: Samedi | B29: Rôti de veau | C29: France | D29: lasagne | E29: France
A30: =A25+1 -> 46179 | B30: Choux brocolis
B31: Fromage | D31: Laitage
B32: Fruit | D32: Fruit
B33: Taboulé | D33: Salade de betterave
A34: Dimanche | B34: Rosbeef | C34: France | D34: brandade de morru | E34: France
A35: =A30+1 -> 46180 | B35: courgette
B36: Fromage | D36: Laitage
B37: Dessert | D37: Fruit

Sheet semaine 24
A1: Menu du : | C1: =A5 -> 46181 | D1: AU | E1: =A35 -> 46187
B2: Midi | D2: Soir
B3: Surimi | D3: Salade de lentille
A4: Lundi | B4: Paupiette de volaille | C4: France | D4: Saucisson brioché | E4: France
A5: ='semaine 23'!A35+1 -> 46181 | B5: Pâtes | D5: rosti
B6: Fromage | D6: Laitage
B7: Fruit | D7: Fruit
B8: Tomates mozzarella | D8: Salade de riz
A9: Mardi | B9: Couscous et | C9: France | D9: Endive au jambon | E9: France
A10: =A5+1 -> 46182 | B10: ses légumes
D11: Laitage
B12: Dessert | D12: Fruit
B13: Salade verte | D13: Cèleri rémoulade
A14: Mercredi | B14: quenelle | C14: France | D14: Poisson bordelaise | E14: France
A15: =A10+1 -> 46183 | B15: petit pois | D15: Haricots verts
B16: Fromage | D16: Laitage
B17: Fruit | D17: Fruit
B18: Avocat | D18: Salade ebly
A19: Jeudi | B19: Rougail saucisse | C19: France | D19: Epinard a la florentine | E19: France
A20: =A15+1 -> 46184 | B20: riz
B21: Fromage | D21: Laitage
B22: Fruit | D22: Fruit
B23: Pizza | D23: Salade composé
A24: Vendredi | B24: Dos de colin | C24: France | D24: tourte champignion | E24: France
A25: =A20+1 -> 46185 | B25: Brocolis
A26: Fêtes famille | B26: Fromage | D26: Laitage
B27: Fruit | D27: Fruit
B28: Asperge | D28: Taboulé
A29: Samedi | B29: Filet mignon de porc | C29: France | D29: Cordon bleu | E29: France
A30: =A25+1 -> 46186 | B30: Pâtes | D30: Poêle de légumes
B31: Fromage | D31: Laitage
B32: Fruit | D32: Fruit
B33: Coquille saint jacques | D33: Salade verte
A34: Dimanche | B34: Hachi Parmentier de canard | C34: France | D34: lasagne saumon | E34: France
A35: =A30+1 -> 46187
B36: Fromage | D36: Laitage
B37: Dessert | D37: Fruit

Sheet semaine 25
A1: Menu du : | C1: =A5 -> 46188 | D1: AU | E1: =A35 -> 46194
B2: Midi | D2: Soir
B3: saucisse sèche
A4: Lundi | B4: escalope de porc | C4: France | D4: Salade de pâtes composé | E4: France
A5: ='semaine 24'!A35+1 -> 46188 | B5: Haricots vert | D5: Roti de dinde
B6: fromage | D6: Laitage
B7: fruit | D7: Fruit
B8: Betteraves | D8: Salade verte
A9: Mardi | B9: Calamar | C9: France | D9: Croque monsieur | E9: France
A10: =A5+1 -> 46189 | B10: Riz
B11: Fromage | D11: Laitage
B12: Fraise | D12: Fruit
B13: Salade pomme de terre | D13: Macédoine
A14: Mercredi | B14: Rôti de veau | C14: France | D14: Jambon braiser | E14: France
A15: =A10+1 -> 46190 | B15: Flan de légume | D15: rösti
B16: Fromage | D16: Laitage
B17: Fruit | D17: Fruit
B18: Carottes Rapée | D18: Salade de pois chiche
A19: Jeudi | C19: France | D19: tomate farci | E19: France
A20: =A15+1 -> 46191 | B20: Pâtes bolo
B21: Fromage | D21: Laitage
B22: Dessert | D22: Fruit
B23: Taboulé | D23: Salade verte
A24: Vendredi | B24: Poisson | C24: France | D24: Quiche | E24: France
A25: =A20+1 -> 46192 | B25: Jardinière de légumes
B26: Fromage | D26: Laitage
B27: Fruit | D27: Fruit
B28: Betteraves | D28: Feuilleté
A29: Samedi | B29: Rosbeef | C29: France | D29: Moussaka | E29: France
A30: =A25+1 -> 46193 | B30: purée
B31: Fromage | D31: Laitage
B32: Fruit | D32: Fruit
B33: Crêpe | D33: Salade verte
A34: Dimanche | B34: Boulette | C34: France | D34: Feuillantine comtoise | E34: France
A35: =A30+1 -> 46194 | B35: Carottes
B36: Fromage | D36: Laitage
B37: Dessert | D37: Fruit

Sheet semaine 26
A1: Menu du : | C1: =A5 -> 46195 | D1: AU | E1: =A35 -> 46201
B2: Midi | D2: Soir
B3: Macédoine | D3: Salade de tomates
A4: Lundi | B4: filet de poulet | C4: France | D4: Cordon bleu | E4: France
A5: ='semaine 25'!A35+1 -> 46195 | B5: salsifis | D5: Pates
B6: Fromage | D6: Laitage
B7: Fruit | D7: Fruit
B8: Salade verte | D8: Salade de riz
A9: Mardi | B9: blanquette de veau | C9: France | D9: Poisson pané | E9: France
A10: =A5+1 -> 46196 | B10: coquillette | D10: Haricots beurre
B11: Fromage | D11: Laitage
B12: Dessert | D12: Fruit
B13: Feuilleté | D13: macédoine
A14: Mercredi | B14: Rôti de porc | C14: France | D14: Merguez | E14: France
A15: =A10+1 -> 46197 | B15: Carotte | D15: Semoule
B16: Fromage | D16: Laitage
B17: Fruit | D17: Fruit
B18: Salade de choux fleur | D18: Salade de lentilles
A19: Jeudi | B19: Steak de bœuf | C19: France | D19: courgette farcie | E19: France
A20: =A15+1 -> 46198 | B20: Gratin dauphinois
B21: Fromage | D21: Laitage
B22: Fruit | D22: Fruit
B23: rosette | D23: Salade verte
A24: Vendredi | B24: Lasagne saumon épinard | C24: France | D24: tourte champignon | E24: France
A25: =A20+1 -> 46199
B26: Fromage | D26: Laitage
B27: Fruit | D27: Fruit
B28: Râpé de courgette | D28: Salade pois chiche
A29: Samedi | B29: Poulet basquaise | C29: France | E29: France
A30: =A25+1 -> 46200 | B30: Riz | D30: Rosbeef froid
B31: Fromage | D31: Laitage
B32: Fruit | D32: Fruit
B33: betterave | D33: Terrine de légumes
A34: Dimanche | B34: Escalope de veau | C34: France | D34: Bouché a la reine | E34: France
A35: =A30+1 -> 46201 | B35: rostie
B36: Fromage | D36: Laitage
B37: Dessert | D37: Fruit

Sheet semaine 27
A1: Menu du : | C1: =A5 -> 46202 | D1: AU | E1: =A35 -> 46208
B2: Midi | D2: Soir
B3: Taboulé | D3: Salade haricots vert
A4: Lundi | B4: Rôti de porc | C4: France | D4: Poisson pané | E4: France
A5: ='semaine 26'!A35+1 -> 46202 | B5: Choux brocolis | D5: Pomme de terre rissolé
B6: Fromage | D6: Laitage
B7: Fruit | D7: Fruit
B8: salade verte | D8: Feuilleté
A9: Mardi | B9: Hambuger | C9: France | D9: Jambon picard | E9: France
A10: =A5+1 -> 46203 | B10: frite
B11: Fromage | D11: Laitage
B12: Dessert | D12: Fruit
B13: Salade de pomme de terre | D13: Carotte râpé
A14: Mercredi | B14: steack | C14: France | D14: Chipolata | E14: France
A15: =A10+1 -> 46204 | B15: Tomate provençal | D15: Lentille
B16: Fromage | D16: Laitage
B17: Fruit | D17: Fruit
B18: Avocat | D18: Tarte à la tomate et chèvre
A19: Jeudi | B19: Sauté de veau | C19: France | D19: Nuggets | E19: France
A20: =A15+1 -> 46205 | B20: Riz | D20: Poêle campagnarde
B21: Fromage | D21: Laitage
B22: Fruit | D22: Fruit
B23: Salade mexicaine | D23: Céleri rémoulade
A24: Vendredi | B24: Blanquette de poisson | C24: France | D24: Boulette de bœuf | E24: France
A25: =A20+1 -> 46206 | B25: Fondu de poireaux | D25: Semoule
B26: Fromage | D26: Laitage
B27: Fruit | D27: Fruit
B28: Salade de betterave-maïs | D28: Salade de pate
A29: Samedi | B29: Escalope de veau | C29: France | D29: Tomate farcie | E29: France
A30: =A25+1 -> 46207 | B30: Pomme de terre vapeur
B31: Fromage | D31: Laitage
B32: Fruit | D32: Fruit
B33: Rosette | D33: Salade césar
A34: Dimanche | B34: Navarin agneau | C34: France | D34: Crêpe au champignon | E34: France
A35: =A30+1 -> 46208 | B35: Flageolet
B36: Fromage | D36: Laitage
B37: Dessert | D37: Fruit

Sheet semaine 28
A1: Menu du : | C1: =A5 -> 46209 | D1: AU | E1: =A35 -> 46215
B2: Midi | D2: Soir
B3: salade de pois chiche | D3: salade verte
A4: Lundi | B4: escalope de volaile | C4: France | D4: Ravioli | E4: France
A5: ='semaine 27'!A35+1 -> 46209 | B5: choux fleur
B6: Fromage | D6: Laitage
B7: Fruit | D7: Fruit
B8: Melon | D8: œuf mayo
A9: Mardi | B9: Moule | C9: France | D9: Pâté de campagne | E9: France
A10: =A5+1 -> 46210 | B10: Frites | D10: carottes
B11: Fromage | D11: Laitage
B12: Dessert | D12: Fruit
B13: Salade de pâtes | D13: Betterave
A14: Mercredi | B14: Rôti de veau | C14: France | D14: gratin de cougettes a la viande | E14: France
A15: =A10+1 -> 46211 | B15: tomate provencal
B16: Fromage | D16: Laitage
B17: Fruit | D17: Fruit
B18: Pastéque | D18: lentille
A19: Jeudi | B19: sauté de poulet | C19: France | D19: Crêpe | E19: France
A20: =A15+1 -> 46212 | B20: haricots blanc
B21: Fromage | D21: Laitage
B22: Fruit | D22: Fruit
B23: Feuilleté | D23: Tomate a la russe ,salade
A24: Vendredi | B24: Poisson | C24: France | D24: Jambon blanc | E24: France
A25: =A20+1 -> 46213 | B25: Ratatouilles
B26: Fromage | D26: Laitage
B27: Fruit | D27: Fruit
B28: taboulé | D28: melon
A29: Samedi | B29: rôtis de bœuf | C29: France | D29: paupiette de volaille | E29: France
A30: =A25+1 -> 46214 | B30: haricots vert | D30: Pates
B31: Fromage | D31: Laitage
B32: Fruit | D32: Banane
B33: mache | D33: salade de riz
A34: Dimanche | B34: langue de bœuf | C34: France | D34: Rôtis de porc froid | E34: France
A35: =A30+1 -> 46215 | B35: pomme de terre
B36: Fromage | D36: Laitage
B37: Dessert | D37: Fruit

Sheet semaine 29
A1: Menu du : | C1: =A5 -> 46216 | D1: AU | E1: =A35 -> 46222
B2: Midi | D2: Soir
B3: salade de tomate | D3: salade ebly
A4: Lundi | B4: steack de bœuf | C4: France | D4: Tender de colin d'Alaska | E4: France
A5: ='semaine 28'!A35+1 -> 46216 | B5: petit pois | D5: haricots beurre
B6: Fromage | D6: Laitage
B7: Fruit | D7: Fruit
B8: Melon
A9: Mardi | B9: magret de canard | C9: France | D9: Salade composée | E9: France
A10: =A5+1 -> 46217 | B10: pomme de terre sauté | D10: Bouché a le reine
B11: Fromage | D11: Laitage
B12: Dessert | D12: Banane
B13: Paté au olive | D13: carotte rapées
A14: Mercredi | B14: saucisse | C14: France | D14: parmentier de canard | E14: France
A15: =A10+1 -> 46218 | B15: courgette
B16: Fromage | D16: Laitage
B17: Fruit | D17: Fruit
B18: salade verte | D18: salade pois chiche
A19: Jeudi | B19: escalope de veau | C19: France | D19: brochette de volaille | E19: France
A20: =A15+1 -> 46219 | B20: pâte | D20: brocolis
B21: Fromage | D21: Laitage
B22: Fruit | D22: Fruit
B23: salade artichaut | D23: poireaux vinaigrette
A24: Vendredi | B24: poisson | C24: France | D24: pate carbonara | E24: France
A25: =A20+1 -> 46220 | B25: blette
B26: Fromage | D26: Laitage
B27: Fruit | D27: Fruit
B28: taboulé | D28: salade de tomate
A29: Samedi | B29: brochette de bœuf | C29: France | D29: tenders de poulet | E29: France
A30: =A25+1 -> 46221 | B30: carottes | D30: rostie
B31: Fromage | D31: Laitage
B32: Fruit | D32: Fruit
B33: terrine de legume | D33: salade verte
A34: Dimanche | B34: sauté de porc | C34: France | D34: Pizza | E34: France
A35: =A30+1 -> 46222 | B35: riz
B36: Fromage | D36: Laitage
B37: Dessert | D37: Fruit

Sheet semaine 30
A1: Menu du : | C1: =A5 -> 46223 | D1: AU | E1: =A35 -> 46229
B2: Midi | D2: Soir
B3: Paté croute | D3: Tomate mozza
A4: Lundi | B4: poulet basquaise | C4: France | D4: Croque monsieur | E4: France
A5: ='semaine 29'!A35+1 -> 46223 | B5: haricots vert
B6: Fromage | D6: Laitage
B7: Fruit | D7: Fruit
B8: mache | D8: salade de perle
A9: Mardi | B9: kebab | C9: France | D9: courgette farci | E9: France
A10: =A5+1 -> 46224 | B10: Frites
B11: Fromage | D11: Laitage
B12: Dessert | D12: Fruit
B13: Pizza | D13: rapé de courgette
A14: Mercredi | B14: roosbeef | C14: France | D14: poisson pané | E14: France
A15: =A10+1 -> 46225 | B15: carotte vichy | D15: riz
B16: Fromage | D16: Laitage
B17: Fruit | D17: Fruit
B18: Pamplemousse | D18: taboulé
A19: Jeudi | B19: Moussaka | C19: France | D19: cordon bleu | E19: France
A20: =A15+1 -> 46226 | D20: brocolis
B21: Fromage | D21: Laitage
B22: Fruit | D22: Fruit
B23: salade de pomme de terre | D23: salade
A24: Vendredi | B24: poisson | C24: France | D24: melon | E24: France
A25: =A20+1 -> 46227 | B25: fondu de poiraux | D25: jambon de pays
B26: Fromage | D26: Laitage
B27: Fruit | D27: Fruit
B28: salade haricots vert | D28: feuilleté
A29: Samedi | B29: sauté de veau | C29: France | D29: œuf dur | E29: France
A30: =A25+1 -> 46228 | B30: pates | D30: épinard
B31: Fromage | D31: Laitage
B32: Fruit | D32: Fruit
B33: coquille saint jacques | D33: salade de choux fleur
A34: Dimanche | B34: roti de porc | C34: France | D34: cannelonie | E34: France
A35: =A30+1 -> 46229 | B35: ratatouille
B36: Fromage | D36: Laitage
B37: Dessert | D37: Fruit

Sheet semaine 31
A1: Menu du : | C1: =A5 -> 46230 | D1: AU | E1: =A35 -> 46236
B2: Midi | D2: Soir
B3: pâté campagne | D3: betterave
A4: Lundi | B4: Endive au jambon | C4: France | D4: poisson bordelaise | E4: France
A5: ='semaine 30'!A35+1 -> 46230 | B5: salsifis | D5: rösti
B6: Fromage | D6: Laitage
B7: Fruit | D7: Fruit
B8: champignon a la grec | D8: salade pois chiche
A9: Mardi | B9: gratin dauphinois | C9: France | D9: choux farci | E9: France
A10: =A5+1 -> 46231 | B10: Saucisses
B11: Fromage | D11: Laitage
B12: religieuse | D12: Fruit
B13: coleslaw | D13: salade de pates
A14: Mercredi | B14: paupiette de volaille | C14: France | D14: rosbeef froid | E14: France
A15: =A10+1 -> 46232 | B15: riz
B16: Fromage | D16: Laitage
B17: Fruit | D17: Fruit
B18: quiche | D18: cèleri rémoulade
A19: Jeudi | B19: courgette farcie ronde | C19: France | D19: feuilleté franc comtois | E19: France
A20: =A15+1 -> 46233
B21: Fromage | D21: Laitage
B22: Fruit | D22: Fruit
B23: poireaux vinaigrette | D23: melon
A24: Vendredi | B24: dos de cabillaud | C24: France | D24: cordon bleu | E24: France
A25: =A20+1 -> 46234 | B25: semoule | D25: haricots plats
B26: Fromage | D26: Laitage
B27: Fruit | D27: Fruit
B28: salade de lentille | D28: salade verte
A29: Samedi | B29: brochette volaille | C29: France | D29: hachi parmentier | E29: France
A30: =A25+1 -> 46235 | B30: jardinière de légumes
B31: Fromage | D31: Laitage
B32: Fruit | D32: Fruit
B33: macédoine | D33: carotte râpé
A34: Dimanche | B34: tripes | C34: France | D34: bouchée a la reine | E34: France
A35: =A30+1 -> 46236 | B35: pomme de terre vapeur
B36: Fromage | D36: Laitage
B37: tarte framboise | D37: Fruit

Sheet semaine 32
A1: Menu du : | C1: =A5 -> 46237 | D1: AU | E1: =A35 -> 46243
B2: Midi | D2: Soir
B3: saucisse séche | D3: salade verte
A4: Lundi | B4: escalope de veau | C4: France | D4: lasagne | E4: France
A5: ='semaine 31'!A35+1 -> 46237 | B5: petit pois
B6: Fromage | D6: Laitage
B7: Fruit | D7: Fruit
B8: nems | D8: taboulé
A9: Mardi | B9: porc au caramel | C9: France | D9: omelette | E9: France
A10: =A5+1 -> 46238 | B10: nouille chinoise | D10: poele de legume
B11: Fromage | D11: Laitage
B12: dessert | D12: Fruit
B13: sardine | D13: celerie remoulade
A14: Mercredi | B14: blanc de poulet | C14: France | D14: jambon blanc | E14: France
A15: =A10+1 -> 46239 | B15: haricots vert | D15: rostie
B16: Fromage | D16: Laitage
B17: Fruit | D17: Fruit
B18: melon | D18: salade mexicaine
A19: Jeudi | B19: gardianne | C19: France | D19: roti de veau | E19: France
A20: =A15+1 -> 46240 | B20: purée | D20: poele de champignion
B21: Fromage | D21: Laitage
B22: Fruit | D22: Fruit
B23: salade de tomate | D23: salade de pate
A24: Vendredi | B24: Anneaux Encornet | C24: France | D24: roti de porc froid | E24: France
A25: =A20+1 -> 46241 | B25: riz
B26: Fromage | D26: Laitage
B27: Fruit | D27: Fruit
B28: feuilleté | D28: coleslo
A29: Samedi | B29: roosbeef | C29: France | D29: brochette | E29: France
A30: =A25+1 -> 46242 | B30: carottes | D30: pomme dauphine
B31: Fromage | D31: Laitage
B32: Fruit | D32: Fruit
B33: pastéque | D33: salade verte
A34: Dimanche | B34: sauté de lapin | C34: France | D34: hachi parmentier | E34: France
A35: =A30+1 -> 46243 | B35: pate
B36: Fromage | D36: Laitage
B37: Dessert | D37: Fruit

Sheet semaine 33
A1: Menu du : | C1: =A5 -> 46244 | D1: AU | E1: =A35 -> 46250
B2: Midi | D2: Soir
B3: salade de pois chiche | D3: salade verte
A4: Lundi | B4: Sauté de porc | C4: France | D4: Ravioli | E4: France
A5: ='semaine 32'!A35+1 -> 46244 | B5: choux fleur
B6: Fromage | D6: Laitage
B7: Fruit | D7: Fruit
B8: Melon | D8: tomate
A9: Mardi | B9: Moule | C9: France | D9: Pâté de campagne | E9: France
A10: =A5+1 -> 46245 | B10: Frites | D10: carottes
B11: Fromage | D11: Laitage
B12: Dessert | D12: Fruit
B13: Salade de pâtes | D13: Betterave
A14: Mercredi | B14: Rôti de veau | C14: France | D14: lasagne saumon | E14: France
A15: =A10+1 -> 46246 | B15: tomate provencal
B16: Fromage | D16: Laitage
B17: Fruit | D17: Fruit
B18: Pastéque | D18: lentille
A19: Jeudi | B19: sauté de poulet | C19: France | D19: Crêpe | E19: France
A20: =A15+1 -> 46247 | B20: haricots blanc
B21: Fromage | D21: Laitage
B22: Fruit | D22: Fruit
B23: carotte rapé | D23: Tomate a la russe ,salade
A24: Vendredi | B24: brandade | C24: France | D24: Jambon blanc | E24: France
A25: =A20+1 -> 46248
B26: Fromage | D26: Laitage
B27: Fruit | D27: Fruit
B28: taboulé | D28: melon
A29: Samedi | B29: rôtis de bœuf | C29: France | D29: paupiette de volaille | E29: France
A30: =A25+1 -> 46249 | B30: haricots vert | D30: Pates
B31: Fromage | D31: Laitage
B32: Fruit | D32: Banane
B33: mache | D33: salade de riz
A34: Dimanche | B34: langue de bœuf | C34: France | D34: Rôtis de porc froid | E34: France
A35: =A30+1 -> 46250 | B35: gratin dauphinois
B36: Fromage | D36: Laitage
B37: Dessert | D37: Fruit

Sheet semaine 34
A1: Menu du : | C1: =A5 -> 46251 | D1: AU | E1: =A35 -> 46257
B2: Midi | D2: Soir
B3: taboulé | D3: celerie remoulade
A4: Lundi | B4: steack de bœuf | C4: France | D4: poisson bordelaise | E4: France
A5: ='semaine 33'!A35+1 -> 46251 | B5: petit pois | D5: haricots beurre
B6: Fromage | D6: Laitage
B7: Fruit | D7: Fruit
B8: Melon | D8: salade piémontaise
A9: Mardi | B9: blanquette de veau | C9: France | D9: Bouché a le reine | E9: France
A10: =A5+1 -> 46252 | B10: riz
B11: Fromage | D11: Laitage
B12: Dessert | D12: Banane
B13: Paté au olive | D13: carotte rapées
A14: Mercredi | B14: saucisse | C14: France | D14: parmentier de canard | E14: France
A15: =A10+1 -> 46253 | B15: lentille
B16: Fromage | D16: Laitage
B17: Fruit | D17: Fruit
B18: Mache | D18: macédoine
A19: Jeudi | B19: Aubergine farcie | C19: France | D19: nugets | E19: France
A20: =A15+1 -> 46254 | D20: rostie
B21: Fromage | D21: Laitage
B22: Fruit | D22: Fruit
B23: salade pois chiche | D23: poireaux vinaigrette
A24: Vendredi | B24: poisson pané | C24: France | D24: salade penne poulet | E24: France
A25: =A20+1 -> 46255 | B25: haricots verts
B26: Fromage | D26: Laitage
B27: Fruit | D27: Fruit
B28: Salade gourmande de céréales | D28: betterave
A29: Samedi | B29: roosbeef | C29: France | D29: cordon bleu | E29: France
A30: =A25+1 -> 46256 | B30: carottes | D30: brocolis
B31: Fromage | D31: Laitage
B32: Fruit | D32: Fruit
B33: terrine de legume | D33: salade verte
A34: Dimanche | B34: tomate farci | C34: France | D34: quiche | E34: France
A35: =A30+1 -> 46257 | B35: riz
B36: Fromage | D36: Laitage
B37: Dessert | D37: Fruit

Sheet semaine 35
A1: Menu du : | C1: =A5 -> 46258 | D1: AU | E1: =A35 -> 46264
B2: Midi | D2: Soir
B3: Paté croute | D3: Taboulé
A4: Lundi | B4: steack haché | C4: France | D4: Croque monsieur | E4: France
A5: ='semaine 34'!A35+1 -> 46258 | B5: haricots vert
B6: Fromage | D6: Laitage
B7: Fruit | D7: Fruit
B8: mache | D8: salade de perle
A9: Mardi | B9: roosbeef | C9: France | D9: courgette farci | E9: France
A10: =A5+1 -> 46259 | B10: truffade cantal
B11: Fromage | D11: Laitage
B12: Dessert | D12: Fruit
B13: Tarte ognion | D13: Coleslaw
A14: Mercredi | B14: Moussaka | C14: France | D14: Ravioli | E14: France
A15: =A10+1 -> 46260
B16: Fromage | D16: Laitage
B17: Fruit | D17: Fruit
B18: salade de lentille | D18: Salade pois chiche
A19: Jeudi | B19: rotis de veau | C19: France | D19: cordon bleu | E19: France
A20: =A15+1 -> 46261 | B20: Flan d'asperge carotte | D20: épinard
B21: Fromage | D21: Laitage
B22: Fruit | D22: Fruit
B23: macédoine | D23: salade de pomme de terre
A24: Vendredi | B24: lasagne saumon | C24: France | D24: melon | E24: France
A25: =A20+1 -> 46262 | D25: jambon de pays
B26: Fromage | D26: Laitage
B27: Fruit | D27: Fruit
B28: Salade crétoise à la fêta | D28: salade de pate
A29: Samedi | B29: choux farci | C29: France | D29: poisson pané | E29: France
A30: =A25+1 -> 46263 | B30: riz | D30: poelé de legume
B31: Fromage | D31: Laitage
B32: Fruit | D32: Fruit
B33: feuilleté | D33: salade de choux fleur
A34: Dimanche | B34: roti de porc | C34: France | D34: Hachi parmentier | E34: France
A35: =A30+1 -> 46264 | B35: ratatouille
B36: Fromage | D36: Laitage
B37: Dessert | D37: Fruit

Sheet semaine 36
A1: Menu du : | C1: =A5 -> 46265 | D1: AU | E1: =A35 -> 46271
B2: Midi | D2: Soir
B3: paté campagne | D3: betterave
A4: Lundi | B4: steack | C4: France | D4: poisson bordelaise | E4: France
A5: ='semaine 35'!A35+1 -> 46265 | B5: salsifi | D5: rostie
B6: Fromage | D6: Laitage
B7: Fruit | D7: Fruit
B8: salade verte | D8: salade pois chiche
A9: Mardi | B9: Aligot | C9: France | D9: ommelette piperade | E9: France
A10: =A5+1 -> 46266 | B10: Saucisses
B11: Fromage | D11: Laitage
B12: Dessert | D12: Fruit
B13: asperge | D13: salade de pates
A14: Mercredi | B14: sauté de volaille | C14: France | D14: rosbeef froid | E14: France
A15: =A10+1 -> 46267 | B15: riz
B16: Fromage | D16: Laitage
B17: Fruit | D17: Fruit
B18: pizza | D18: tomate antiboise
A19: Jeudi | B19: gigot agneaux | C19: France | D19: feuillé francomtois | E19: France
A20: =A15+1 -> 46268 | B20: choux romanesco
B21: Fromage | D21: Laitage
B22: Fruit | D22: Fruit
B23: poireaux vignairette | D23: melon
A24: Vendredi | B24: saumon | C24: France | D24: cordon bleu | E24: France
A25: =A20+1 -> 46269 | B25: semoule | D25: haricots plats
B26: Fromage | D26: Laitage
B27: Fruit | D27: Fruit
B28: salade de lentille | D28: salade verte
A29: Samedi | B29: brochette | C29: France | D29: pate a la bolo | E29: France
A30: =A25+1 -> 46270 | B30: jardiniére de legume
B31: Fromage | D31: Laitage
B32: Fruit | D32: Fruit
B33: macédoine | D33: carrotte rapé
A34: Dimanche | B34: trippe | C34: France | D34: bouchee a la reine | E34: France
A35: =A30+1 -> 46271 | B35: pomme de terre vapeur
B36: Fromage | D36: Laitage
B37: Dessert | D37: Fruit

Sheet semaine 37
A1: Menu du : | C1: =A5 -> 46272 | D1: AU | E1: =A35 -> 46278
B2: Midi | D2: Soir
B3: saucisse séche | D3: salade verte
